<?xml version="1.0" ?>
<!-- =================================================================================== -->
<!-- |    This document was autogenerated by xacro from my_robot_integration.urdf.xacro | -->
<!-- |    EDITING THIS FILE BY HAND IS NOT RECOMMENDED                                 | -->
<!-- =================================================================================== -->
<!-- Name your robot here -->
<robot name="alt_car_assembly">
  <link name="dummy_link"/>
  <joint name="dummy_joint" type="fixed">
    <parent link="dummy_link"/>
    <child link="chassis"/>
  </joint>
  <link name="chassis">
    <inertial>
      <origin rpy="0 0 0" xyz="-1.13008383898424E-16 0.0127 1.1234963901515E-16"/>
      <mass value="17.2299101764948"/>
      <inertia ixx="1.32974914515101" ixy="2.11758236813575E-20" ixz="-3.01120212748904E-16" iyy="2.05043247302463" iyz="2.11758236813573E-20" izz="0.722536002681863"/>
    </inertial>
    <visual>
      <origin rpy="0 0 0" xyz="0 0 0"/>
      <geometry>
        <mesh filename="package://alt_car_assembly/meshes/chassis.STL"/>
      </geometry>
      <material name="">
        <color rgba="0.792156862745098 0.819607843137255 0.933333333333333 1"/>
      </material>
    </visual>
    <collision>
      <origin rpy="0 0 0" xyz="0 0 0"/>
      <geometry>
        <mesh filename="package://alt_car_assembly/meshes/chassis.STL"/>
      </geometry>
    </collision>
  </link>
  <link name="hub_f_l">
    <inertial>
      <origin rpy="0 0 0" xyz="0 0.0324625099031435 0"/>
      <mass value="0.334738405845382"/>
      <inertia ixx="0.000566787961434065" ixy="-1.39410525233639E-19" ixz="2.10064170919066E-19" iyy="0.000587960662686382" iyz="7.40129452315766E-20" izz="0.000875439911652352"/>
    </inertial>
    <visual>
      <origin rpy="0 0 0" xyz="0 0 0"/>
      <geometry>
        <mesh filename="package://alt_car_assembly/meshes/hub_f_l.STL"/>
      </geometry>
      <material name="">
        <color rgba="0.792156862745098 0.819607843137255 0.933333333333333 1"/>
      </material>
    </visual>
    <collision>
      <origin rpy="0 0 0" xyz="0 0 0"/>
      <geometry>
        <mesh filename="package://alt_car_assembly/meshes/hub_f_l.STL"/>
      </geometry>
    </collision>
  </link>
  <joint name="front_left_steering" type="revolute">
    <origin rpy="-1.5708 0 0" xyz="0.254 -0.34677 0"/>
    <parent link="chassis"/>
    <child link="hub_f_l"/>
    <axis xyz="0 1 0"/>
    <limit effort="10" lower="-3.14" upper="3.14" velocity="1"/>
  </joint>
  <link name="wheel_f_l">
    <inertial>
      <origin rpy="0 0 0" xyz="-3.88578058618805E-16 1.38777878078145E-17 -2.22044604925031E-16"/>
      <mass value="0.926666637773504"/>
      <inertia ixx="0.00141988958906164" ixy="-1.64129739327946E-37" ixz="-2.43945488809238E-19" iyy="0.00141988958906164" iyz="-4.69349834934246E-36" izz="0.00194300680608435"/>
    </inertial>
    <visual>
      <origin rpy="0 0 0" xyz="0 0 0"/>
      <geometry>
        <mesh filename="package://alt_car_assembly/meshes/wheel_f_l.STL"/>
      </geometry>
      <material name="">
        <color rgba="0.792156862745098 0.819607843137255 0.933333333333333 1"/>
      </material>
    </visual>
    <collision>
      <origin rpy="0 0 0" xyz="0 0 0"/>
      <geometry>
        <mesh filename="package://alt_car_assembly/meshes/wheel_f_l.STL"/>
      </geometry>
    </collision>
  </link>
  <joint name="front_left_axle" type="continuous">
    <origin rpy="0 -1.5708 0" xyz="0 0.08255 0"/>
    <parent link="hub_f_l"/>
    <child link="wheel_f_l"/>
    <axis xyz="0 0 1"/>
    <limit effort="100" velocity="10"/>
  </joint>
  <link name="hub_f_r">
    <inertial>
      <origin rpy="0 0 0" xyz="0 0.0324625099031435 0"/>
      <mass value="0.334738405845383"/>
      <inertia ixx="0.000566787961434066" ixy="-3.32625042313524E-21" ixz="-1.93970544921235E-19" iyy="0.000587960662686382" iyz="-8.83716172998184E-22" izz="0.000875439911652352"/>
    </inertial>
    <visual>
      <origin rpy="0 0 0" xyz="0 0 0"/>
      <geometry>
        <mesh filename="package://alt_car_assembly/meshes/hub_f_r.STL"/>
      </geometry>
      <material name="">
        <color rgba="0.792156862745098 0.819607843137255 0.933333333333333 1"/>
      </material>
    </visual>
    <collision>
      <origin rpy="0 0 0" xyz="0 0 0"/>
      <geometry>
        <mesh filename="package://alt_car_assembly/meshes/hub_f_r.STL"/>
      </geometry>
    </collision>
  </link>
  <joint name="front_right_steering" type="revolute">
    <origin rpy="-1.5708 0 0" xyz="-0.254 -0.34677 0"/>
    <parent link="chassis"/>
    <child link="hub_f_r"/>
    <axis xyz="0 1 0"/>
    <limit effort="10" lower="-3.14" upper="3.14" velocity="1"/>
  </joint>
  <link name="wheel_f_r">
    <inertial>
      <origin rpy="0 0 0" xyz="5.55111512312578E-17 0 0"/>
      <mass value="0.926666637773504"/>
      <inertia ixx="0.00141988958906164" ixy="-1.6412973932795E-37" ixz="3.40507244796229E-19" iyy="0.00141988958906164" iyz="-4.69349834934245E-36" izz="0.00194300680608435"/>
    </inertial>
    <visual>
      <origin rpy="0 0 0" xyz="0 0 0"/>
      <geometry>
        <mesh filename="package://alt_car_assembly/meshes/wheel_f_r.STL"/>
      </geometry>
      <material name="">
        <color rgba="0.792156862745098 0.819607843137255 0.933333333333333 1"/>
      </material>
    </visual>
    <collision>
      <origin rpy="0 0 0" xyz="0 0 0"/>
      <geometry>
        <mesh filename="package://alt_car_assembly/meshes/wheel_f_r.STL"/>
      </geometry>
    </collision>
  </link>
  <joint name="front_right_axle" type="continuous">
    <origin rpy="0 -1.5708 0" xyz="0 0.08255 0"/>
    <parent link="hub_f_r"/>
    <child link="wheel_f_r"/>
    <axis xyz="0 0 1"/>
    <limit effort="100" velocity="10"/>
  </joint>
  <link name="hub_r_r">
    <inertial>
      <origin rpy="0 0 0" xyz="-5.55111512312578E-17 0.0578625099031435 5.55111512312578E-17"/>
      <mass value="0.334738405845382"/>
      <inertia ixx="0.000566787961434064" ixy="1.32149634801042E-19" ixz="-9.49695306454753E-20" iyy="0.000587960662686381" iyz="2.25089532101838E-22" izz="0.000875439911652351"/>
    </inertial>
    <visual>
      <origin rpy="0 0 0" xyz="0 0 0"/>
      <geometry>
        <mesh filename="package://alt_car_assembly/meshes/hub_r_r.STL"/>
      </geometry>
      <material name="">
        <color rgba="0.792156862745098 0.819607843137255 0.933333333333333 1"/>
      </material>
    </visual>
    <collision>
      <origin rpy="0 0 0" xyz="0 0 0"/>
      <geometry>
        <mesh filename="package://alt_car_assembly/meshes/hub_r_r.STL"/>
      </geometry>
    </collision>
  </link>
  <joint name="rear_right_steering" type="fixed">
    <origin rpy="-1.5708 0 3.1416" xyz="-0.254 0.34677 0.0254"/>
    <parent link="chassis"/>
    <child link="hub_r_r"/>
    <axis xyz="0 0 0"/>
  </joint>
  <link name="wheel_r_r">
    <inertial>
      <origin rpy="0 0 0" xyz="-5.55111512312578E-17 0 1.66533453693773E-16"/>
      <mass value="0.926666637773503"/>
      <inertia ixx="0.00141988958906164" ixy="-1.64129739327948E-37" ixz="1.94682052891282E-19" iyy="0.00141988958906164" iyz="-4.69349834934246E-36" izz="0.00194300680608435"/>
    </inertial>
    <visual>
      <origin rpy="0 0 0" xyz="0 0 0"/>
      <geometry>
        <mesh filename="package://alt_car_assembly/meshes/wheel_r_r.STL"/>
      </geometry>
      <material name="">
        <color rgba="0.792156862745098 0.819607843137255 0.933333333333333 1"/>
      </material>
    </visual>
    <collision>
      <origin rpy="0 0 0" xyz="0 0 0"/>
      <geometry>
        <mesh filename="package://alt_car_assembly/meshes/wheel_r_r.STL"/>
      </geometry>
    </collision>
  </link>
  <joint name="rear_right_axle" type="continuous">
    <origin rpy="3.1416 1.5708 0" xyz="0 0.10795 0"/>
    <parent link="hub_r_r"/>
    <child link="wheel_r_r"/>
    <axis xyz="0 0 1"/>
    <limit effort="100" velocity="10"/>
  </joint>
  <link name="hub_r_l">
    <inertial>
      <origin rpy="0 0 0" xyz="5.55111512312578E-17 0.0578625099031435 0"/>
      <mass value="0.334738405845383"/>
      <inertia ixx="0.000566787961434065" ixy="-1.60454472242266E-19" ixz="-4.92158596450278E-20" iyy="0.000587960662686383" iyz="-1.01861746001102E-19" izz="0.000875439911652353"/>
    </inertial>
    <visual>
      <origin rpy="0 0 0" xyz="0 0 0"/>
      <geometry>
        <mesh filename="package://alt_car_assembly/meshes/hub_r_l.STL"/>
      </geometry>
      <material name="">
        <color rgba="0.792156862745098 0.819607843137255 0.933333333333333 1"/>
      </material>
    </visual>
    <collision>
      <origin rpy="0 0 0" xyz="0 0 0"/>
      <geometry>
        <mesh filename="package://alt_car_assembly/meshes/hub_r_l.STL"/>
      </geometry>
    </collision>
  </link>
  <joint name="rear_left_steering" type="fixed">
    <origin rpy="-1.5708 0 3.1416" xyz="0.254 0.34677 0.0254"/>
    <parent link="chassis"/>
    <child link="hub_r_l"/>
    <axis xyz="0 0 0"/>
  </joint>
  <link name="wheel_r_l">
    <inertial>
      <origin rpy="0 0 0" xyz="5.55111512312578E-17 0 5.55111512312578E-17"/>
      <mass value="0.926666637773504"/>
      <inertia ixx="0.00141988958906164" ixy="-1.64129739327944E-37" ixz="1.89278381288076E-19" iyy="0.00141988958906164" iyz="-4.69349834934246E-36" izz="0.00194300680608435"/>
    </inertial>
    <visual>
      <origin rpy="0 0 0" xyz="0 0 0"/>
      <geometry>
        <mesh filename="package://alt_car_assembly/meshes/wheel_r_l.STL"/>
      </geometry>
      <material name="">
        <color rgba="0.792156862745098 0.819607843137255 0.933333333333333 1"/>
      </material>
    </visual>
    <collision>
      <origin rpy="0 0 0" xyz="0 0 0"/>
      <geometry>
        <mesh filename="package://alt_car_assembly/meshes/wheel_r_l.STL"/>
      </geometry>
    </collision>
  </link>
  <joint name="rear_left_axle" type="continuous">
    <origin rpy="3.1416 1.5708 0" xyz="0 0.10795 0"/>
    <parent link="hub_r_l"/>
    <child link="wheel_r_l"/>
    <axis xyz="0 0 1"/>
    <limit effort="100" velocity="10"/>
  </joint>
  <transmission name="simple_trans">
    <type>transmission_interface/SimpleTransmission</type>
    <joint name="front_right_steering">
      <hardwareInterface>hardware_interface/EffortJointInterface</hardwareInterface>
    </joint>
    <actuator name="right_steering">
      <mechanicalReduction>50</mechanicalReduction>
      <hardwareInterface>hardware_interface/EffortJointInterface</hardwareInterface>
    </actuator>
  </transmission>
  <transmission name="simple_trans_2">
    <type>transmission_interface/SimpleTransmission</type>
    <joint name="front_left_steering">
      <hardwareInterface>hardware_interface/EffortJointInterface</hardwareInterface>
    </joint>
    <actuator name="left_steering">
      <mechanicalReduction>50</mechanicalReduction>
      <hardwareInterface>hardware_interface/EffortJointInterface</hardwareInterface>
    </actuator>
  </transmission>
  <transmission name="simple_trans_3">
    <type>transmission_interface/SimpleTransmission</type>
    <joint name="rear_left_axle">
      <hardwareInterface>hardware_interface/VelocityJointInterface</hardwareInterface>
    </joint>
    <actuator name="left_drive">
      <mechanicalReduction>50</mechanicalReduction>
      <hardwareInterface>hardware_interface/VelocityJointInterface</hardwareInterface>
    </actuator>
  </transmission>
  <transmission name="simple_trans_4">
    <type>transmission_interface/SimpleTransmission</type>
    <joint name="rear_right_axle">
      <hardwareInterface>hardware_interface/VelocityJointInterface</hardwareInterface>
    </joint>
    <actuator name="right_drive">
      <mechanicalReduction>50</mechanicalReduction>
      <hardwareInterface>hardware_interface/VelocityJointInterface</hardwareInterface>
    </actuator>
  </transmission>
  <gazebo>
    <plugin filename="libgazebo_ros_control.so" name="gazebo_ros_control">
    </plugin>
  </gazebo>
  <link name="base_laser">
    <inertial>
      <origin rpy="0 0 0" xyz="-0.00029774 0.0066667 0.00013047"/>
      <mass value="0.15717"/>
      <inertia ixx="6.7885E-05" ixy="-1.3987E-07" ixz="-8.1554E-07" iyy="0.00013173" iyz="-9.0932E-08" izz="7.1972E-05"/>
    </inertial>
    <visual>
      <origin rpy="0 0 0" xyz="0 0 0"/>
      <geometry>
        <mesh filename="package://alt_car_assembly/meshes/ydlidar.dae"/>
      </geometry>
      <material name="">
        <color rgba="0.64706 0.61961 0.58824 1"/>
      </material>
    </visual>
    <collision>
      <origin rpy="0 0 0" xyz="0 0 0"/>
      <geometry>
        <mesh filename="package://alt_car_assembly/meshes/ydlidar.dae"/>
      </geometry>
    </collision>
  </link>
  <link name="laser_frame">
    <inertial>
      <origin rpy="0 0 0" xyz="-0.00036659 0.00064155 -0.00027052"/>
      <mass value="0.25482"/>
      <inertia ixx="8.9194E-05" ixy="1.8116E-07" ixz="3.6435E-08" iyy="0.00018279" iyz="2.423E-07" izz="0.00011103"/>
    </inertial>
    <!--visual>
      <origin
        xyz="0 0 0"
        rpy="0 0 0" />
      <geometry>
        <mesh
          filename="package://ydlidar_ros/meshes/ydlidar.dae" />
      </geometry>
      <material
        name="">
        <color
          rgba="0.64706 0.61961 0.58824 1" />
      </material>
    </visual-->
    <!--collision>
      <origin
        xyz="0 0 0"
        rpy="0 0 0" />
      <geometry>
        <mesh
          filename="package://ydlidar_ros/meshes/ydlidar.dae" />
      </geometry>
    </collision-->
  </link>
  <joint name="laser_joint" type="fixed">
    <origin rpy="0 0 0" xyz="0 0 0.03172"/>
    <parent link="base_laser"/>
    <child link="laser_frame"/>
    <axis xyz="0 0 0"/>
  </joint>
  <!-- Add your gazebo sensors here -->

  <gazebo reference="base_laser">
    <!-- <gravity>true</gravity> -->
    <!-- Gazebo has fixed set of Sensors types. Check them out here <> -->
    <sensor name="laser" type="ray"> 
      <!-- Add in your sensor characteristics -->
      <pose> 0 0 0 0 0 0 </pose>
      <visualise>true</visualise>
      <update_rate>40</update_rate>
      <!-- <always_on>true</always_on> -->
      <ray>
        <scan>
          <horizontal>
            <samples>720</samples>
            <resolution>1</resolution>
            <min_angle>-1.570796</min_angle>
                    <max_angle>1.570796</max_angle>
                  </horizontal>
                </scan>
                <range>
                  <min>0.10</min>
                  <max>30.0</max>
                  <resolution>0.01</resolution>
                </range>
                <noise>
                  <type>gaussian</type>
                  <mean>0.0</mean>
                  <stddev>0.01</stddev>
                </noise>
            </ray>
            <plugin name="gazebo_ros_head_hokuyo_controller" filename="libgazebo_ros_laser.so">
              <!-- Use topic name as /my_robot/scan -->
        <topicName>/scan</topicName> 
        <frameName>laser_frame</frameName>
      </plugin>
    </sensor>
  </gazebo>
  <!--  Gazebo plugin for control here is already added for you -->
  <!-- 
  <gazebo>
    <plugin filename="libgazebo_ros_control.so" name="gazebo_ros_control">
      
      <robotSimType>gazebo_ros_control/DefaultRobotHWSim</robotSimType>
      <legacyModeNS>true</legacyModeNS>
    </plugin>
  </gazebo> -->
  <!-- Create a joint between your robot and sensor -->

  <joint name="chassis_laser_joint" type="fixed">
    <origin rpy="0 0 0" xyz="0 0 0.03172"/>
    <parent link="chassis"/>
    <child link="base_laser"/>
    <axis xyz="0 0 0"/>
  </joint>
</robot>



